Workbook

Sheet Overview
A1: Polynomial Regression — Step-by-Step Workbook (fully formula-driven)
A2: Ld_uH and Lq_uH as f(Id_ref, Iq_ref) | Degree-4 polynomial | Every value computed from cross-sheet formulas
A4: Sheet | B4: What it shows
A5: Raw_Data | B5: The 77 original measurements. All other sheets pull from here.
A6: Step1_Features | B6: 15 polynomial feature columns computed from Id & Iq via formulas (=B4^2 etc).
A7: Step2_Ld_XtX | B7: XᵀX matrix — each cell = SUMPRODUCT of two feature columns from Step1. Xᵀy = SUMPRODUCT of feature × Ld.
A8: Step3_Ld_Coefs | B8: β coefficients via =MMULT(MINVERSE(XᵀX), Xᵀy). Contributions at example point via =D_coef * F_feature.
A9: Step4_Ld_Preds | B9: Predicted Ld per row = SUMPRODUCT(coefficients, features for that row). Error = Actual − Predicted.
A10: Step5_Ld_Formula | B10: Final formula with coefficients pulled from Step3. Change A6/B6 to evaluate at any point.
A11: Step2_Lq_XtX | B11: Same as Step2 but Xᵀy uses Lq column from Raw_Data.
A12: Step3_Lq_Coefs | B12: β coefficients for Lq.
A13: Step4_Lq_Preds | B13: Predicted Lq per row.
A14: Step5_Lq_Formula | B14: Final formula for Lq.

Sheet Raw_Data
A1: Raw Data — 77 measurement points
A2: Row | B2: Id_ref (A) | C2: Iq_ref (A) | D2: Ld_uH (µH) | E2: Lq_uH (µH)
A3: 1 | B3: 0 | C3: 0 | D3: 500.41526 | E3: 499.06425
A4: 2 | B4: 0 | C4: 0 | D4: 501.00862 | E4: 498.47149
A5: 3 | B5: 0 | C5: 0 | D5: 501.26213 | E5: 498.21917
A6: 4 | B6: 0 | C6: 0 | D6: 501.10672 | E6: 498.3728
A7: 5 | B7: 0 | C7: 0 | D7: 500.58529 | E7: 498.89411
A8: 6 | B8: 0 | C8: 0 | D8: 499.83822 | E8: 499.64173
A9: 7 | B9: 0 | C9: 0 | D9: 499.06435 | E9: 500.41567
A10: 8 | B10: 0 | C10: 10.280355 | D10: 499.15296 | E10: 497.85521
A11: 9 | B11: -2.660752 | C11: 9.930061 | D11: 500.50879 | E11: 498.09765
A12: 10 | B12: -5.140178 | C12: 8.903049 | D12: 501.47484 | E12: 498.58684
A13: 11 | B13: -7.269309 | C13: 7.269309 | D13: 501.85677 | E13: 499.30827
A14: 12 | B14: -8.903049 | C14: 5.140178 | D14: 501.77728 | E14: 500.23982
... A79: 77 | B79: -102.80355 | C79: 0 | D79: 494.20608 | E79: 495.48275

Sheet Step1_Features
A1: Step 1 — Feature Expansion: 15 polynomial terms computed from Id and Iq
A2: Inputs (from Raw_Data) | C2: Computed features X (77 rows × 15 columns)
A3: Row | B3: Id_ref | C3: Iq_ref | D3: 1 (constant) | E3: Id | F3: Iq | G3: Id² | H3: Id·Iq | I3: Iq² | J3: Id³ | K3: Id²·Iq | L3: Id·Iq² | M3: Iq³ | N3: Id⁴ | O3: Id³·Iq | P3: Id²·Iq² | Q3: Id·Iq³ | R3: Iq⁴
A4: 1 | B4: =Raw_Data!B3 -> 0 | C4: =Raw_Data!C3 -> 0 | D4: =1 -> 1 | E4: =B4 -> 0 | F4: =C4 -> 0 | G4: =B4^2 -> 0 | H4: =B4*C4 -> 0 | I4: =C4^2 -> 0 | J4: =B4^3 -> 0 | K4: =B4^2*C4 -> 0 | L4: =B4*C4^2 -> 0 | M4: =C4^3 -> 0 | N4: =B4^4 -> 0 | O4: =B4^3*C4 -> 0 | P4: =B4^2*C4^2 -> 0 | Q4: =B4*C4^3 -> 0 | R4: =C4^4 -> 0
A5: 2 | B5: =Raw_Data!B4 -> 0 | C5: =Raw_Data!C4 -> 0 | D5: =1 -> 1 | E5: =B5 -> 0 | F5: =C5 -> 0 | G5: =B5^2 -> 0 | H5: =B5*C5 -> 0 | I5: =C5^2 -> 0 | J5: =B5^3 -> 0 | K5: =B5^2*C5 -> 0 | L5: =B5*C5^2 -> 0 | M5: =C5^3 -> 0 | N5: =B5^4 -> 0 | O5: =B5^3*C5 -> 0 | P5: =B5^2*C5^2 -> 0 | Q5: =B5*C5^3 -> 0 | R5: =C5^4 -> 0
A6: 3 | B6: =Raw_Data!B5 -> 0 | C6: =Raw_Data!C5 -> 0 | D6: =1 -> 1 | E6: =B6 -> 0 | F6: =C6 -> 0 | G6: =B6^2 -> 0 | H6: =B6*C6 -> 0 | I6: =C6^2 -> 0 | J6: =B6^3 -> 0 | K6: =B6^2*C6 -> 0 | L6: =B6*C6^2 -> 0 | M6: =C6^3 -> 0 | N6: =B6^4 -> 0 | O6: =B6^3*C6 -> 0 | P6: =B6^2*C6^2 -> 0 | Q6: =B6*C6^3 -> 0 | R6: =C6^4 -> 0
A7: 4 | B7: =Raw_Data!B6 -> 0 | C7: =Raw_Data!C6 -> 0 | D7: =1 -> 1 | E7: =B7 -> 0 | F7: =C7 -> 0 | G7: =B7^2 -> 0 | H7: =B7*C7 -> 0 | I7: =C7^2 -> 0 | J7: =B7^3 -> 0 | K7: =B7^2*C7 -> 0 | L7: =B7*C7^2 -> 0 | M7: =C7^3 -> 0 | N7: =B7^4 -> 0 | O7: =B7^3*C7 -> 0 | P7: =B7^2*C7^2 -> 0 | Q7: =B7*C7^3 -> 0 | R7: =C7^4 -> 0
A8: 5 | B8: =Raw_Data!B7 -> 0 | C8: =Raw_Data!C7 -> 0 | D8: =1 -> 1 | E8: =B8 -> 0 | F8: =C8 -> 0 | G8: =B8^2 -> 0 | H8: =B8*C8 -> 0 | I8: =C8^2 -> 0 | J8: =B8^3 -> 0 | K8: =B8^2*C8 -> 0 | L8: =B8*C8^2 -> 0 | M8: =C8^3 -> 0 | N8: =B8^4 -> 0 | O8: =B8^3*C8 -> 0 | P8: =B8^2*C8^2 -> 0 | Q8: =B8*C8^3 -> 0 | R8: =C8^4 -> 0
A9: 6 | B9: =Raw_Data!B8 -> 0 | C9: =Raw_Data!C8 -> 0 | D9: =1 -> 1 | E9: =B9 -> 0 | F9: =C9 -> 0 | G9: =B9^2 -> 0 | H9: =B9*C9 -> 0 | I9: =C9^2 -> 0 | J9: =B9^3 -> 0 | K9: =B9^2*C9 -> 0 | L9: =B9*C9^2 -> 0 | M9: =C9^3 -> 0 | N9: =B9^4 -> 0 | O9: =B9^3*C9 -> 0 | P9: =B9^2*C9^2 -> 0 | Q9: =B9*C9^3 -> 0 | R9: =C9^4 -> 0
A10: 7 | B10: =Raw_Data!B9 -> 0 | C10: =Raw_Data!C9 -> 0 | D10: =1 -> 1 | E10: =B10 -> 0 | F10: =C10 -> 0 | G10: =B10^2 -> 0 | H10: =B10*C10 -> 0 | I10: =C10^2 -> 0 | J10: =B10^3 -> 0 | K10: =B10^2*C10 -> 0 | L10: =B10*C10^2 -> 0 | M10: =C10^3 -> 0 | N10: =B10^4 -> 0 | O10: =B10^3*C10 -> 0 | P10: =B10^2*C10^2 -> 0 | Q10: =B10*C10^3 -> 0 | R10: =C10^4 -> 0
A11: 8 | B11: =Raw_Data!B10 -> 0 | C11: =Raw_Data!C10 -> 10.280355 | D11: =1 -> 1 | E11: =B11 -> 0 | F11: =C11 -> 10.280355 | G11: =B11^2 -> 0 | H11: =B11*C11 -> 0 | I11: =C11^2 -> 105.6857 | J11: =B11^3 -> 0 | K11: =B11^2*C11 -> 0 | L11: =B11*C11^2 -> 0 | M11: =C11^3 -> 1086.4865 | N11: =B11^4 -> 0 | O11: =B11^3*C11 -> 0 | P11: =B11^2*C11^2 -> 0 | Q11: =B11*C11^3 -> 0 | R11: =C11^4 -> 11169.467
A12: 9 | B12: =Raw_Data!B11 -> -2.660752 | C12: =Raw_Data!C11 -> 9.930061 | D12: =1 -> 1 | E12: =B12 -> -2.660752 | F12: =C12 -> 9.930061 | G12: =B12^2 -> 7.0796012 | H12: =B12*C12 -> -26.42143 | I12: =C12^2 -> 98.606111 | J12: =B12^3 -> -18.837063 | K12: =B12^2*C12 -> 70.300872 | L12: =B12*C12^2 -> -262.36641 | M12: =C12^3 -> 979.1647 | N12: =B12^4 -> 50.120753 | O12: =B12^3*C12 -> -187.05319 | P12: =B12^2*C12^2 -> 698.09195 | Q12: =B12*C12^3 -> -2605.3144 | R12: =C12^4 -> 9723.1652
A13: 10 | B13: =Raw_Data!B12 -> -5.140178 | C13: =Raw_Data!C12 -> 8.903049 | D13: =1 -> 1 | E13: =B13 -> -5.140178 | F13: =C13 -> 8.903049 | G13: =B13^2 -> 26.42143 | H13: =B13*C13 -> -45.763257 | I13: =C13^2 -> 79.264281 | J13: =B13^3 -> -135.81085 | K13: =B13^2*C13 -> 235.23128 | L13: =B13*C13^2 -> -407.43252 | M13: =C13^3 -> 705.69378 | N13: =B13^4 -> 698.09196 | O13: =B13^3*C13 -> -1209.1307 | P13: =B13^2*C13^2 -> 2094.2757 | Q13: =B13*C13^3 -> -3627.3917 | R13: =C13^4 -> 6282.8263
A14: 11 | B14: =Raw_Data!B13 -> -7.269309 | C14: =Raw_Data!C13 -> 7.269309 | D14: =1 -> 1 | E14: =B14 -> -7.269309 | F14: =C14 -> 7.269309 | G14: =B14^2 -> 52.842853 | H14: =B14*C14 -> -52.842853 | I14: =C14^2 -> 52.842853 | J14: =B14^3 -> -384.13103 | K14: =B14^2*C14 -> 384.13103 | L14: =B14*C14^2 -> -384.13103 | M14: =C14^3 -> 384.13103 | N14: =B14^4 -> 2792.3671 | O14: =B14^3*C14 -> -2792.3671 | P14: =B14^2*C14^2 -> 2792.3671 | Q14: =B14*C14^3 -> -2792.3671 | R14: =C14^4 -> 2792.3671
A15: 12 | B15: =Raw_Data!B14 -> -8.903049 | C15: =Raw_Data!C14 -> 5.140178 | D15: =1 -> 1 | E15: =B15 -> -8.903049 | F15: =C15 -> 5.140178 | G15: =B15^2 -> 79.264281 | H15: =B15*C15 -> -45.763257 | I15: =C15^2 -> 26.42143 | J15: =B15^3 -> -705.69378 | K15: =B15^2*C15 -> 407.43252 | L15: =B15*C15^2 -> -235.23128 | M15: =C15^3 -> 135.81085 | N15: =B15^4 -> 6282.8263 | O15: =B15^3*C15 -> -3627.3917 | P15: =B15^2*C15^2 -> 2094.2757 | Q15: =B15*C15^3 -> -1209.1307 | R15: =C15^4 -> 698.09196
... A80: 77 | B80: =Raw_Data!B79 -> -102.80355 | C80: =Raw_Data!C79 -> 0 | D80: =1 -> 1 | E80: =B80 -> -102.80355 | F80: =C80 -> 0 | G80: =B80^2 -> 10568.571 | H80: =B80*C80 -> 0 | I80: =C80^2 -> 0 | J80: =B80^3 -> -1086486.6 | K80: =B80^2*C80 -> 0 | L80: =B80*C80^2 -> 0 | M80: =C80^3 -> 0 | N80: =B80^4 -> 1.1169468e+08 | O80: =B80^3*C80 -> 0 | P80: =B80^2*C80^2 -> 0 | Q80: =B80*C80^3 -> 0 | R80: =C80^4 -> 0

Sheet Step2_Ld_XtX
A1: Step 2 — XᵀX matrix (15×15) for Ld fit | Each cell = SUMPRODUCT of two feature columns from Step1
A2: Feature | B2: XᵀX — every cell =SUMPRODUCT(col_i of Step1, col_j of Step1)
A3: Feature | B3: 1 (constant) | C3: Id | D3: Iq | E3: Id² | F3: Id·Iq | G3: Iq² | H3: Id³ | I3: Id²·Iq | J3: Id·Iq² | K3: Iq³ | L3: Id⁴ | M3: Id³·Iq | N3: Id²·Iq² | O3: Id·Iq³ | P3: Iq⁴
A4: 1 (constant) | B4: =SUMPRODUCT(Step1_Features!D$4:D$80,Step1_Features!D$4:D$80) -> 77 | C4: =SUMPRODUCT(Step1_Features!D$4:D$80,Step1_Features!E$4:E$80) -> -2430.1037 | D4: =SUMPRODUCT(Step1_Features!D$4:D$80,Step1_Features!F$4:F$80) -> 2430.1037 | E4: =SUMPRODUCT(Step1_Features!D$4:D$80,Step1_Features!G$4:G$80) -> 142411.49 | F4: =SUMPRODUCT(Step1_Features!D$4:D$80,Step1_Features!H$4:H$80) -> -75926.702 | G4: =SUMPRODUCT(Step1_Features!D$4:D$80,Step1_Features!I$4:I$80) -> 142411.49 | H4: =SUMPRODUCT(Step1_Features!D$4:D$80,Step1_Features!J$4:J$80) -> -10013125 | I4: =SUMPRODUCT(Step1_Features!D$4:D$80,Step1_Features!K$4:K$80) -> 4112372.5 | J4: =SUMPRODUCT(Step1_Features!D$4:D$80,Step1_Features!L$4:L$80) -> -4112372.5 | K4: =SUMPRODUCT(Step1_Features!D$4:D$80,Step1_Features!M$4:M$80) -> 10013125 | L4: =SUMPRODUCT(Step1_Features!D$4:D$80,Step1_Features!N$4:N$80) -> 7.781294e+08 | M4: =SUMPRODUCT(Step1_Features!D$4:D$80,Step1_Features!O$4:O$80) -> -2.6400168e+08 | N4: =SUMPRODUCT(Step1_Features!D$4:D$80,Step1_Features!P$4:P$80) -> 2.1221711e+08 | O4: =SUMPRODUCT(Step1_Features!D$4:D$80,Step1_Features!Q$4:Q$80) -> -2.6400168e+08 | P4: =SUMPRODUCT(Step1_Features!D$4:D$80,Step1_Features!R$4:R$80) -> 7.781294e+08
A5: Id | B5: =SUMPRODUCT(Step1_Features!E$4:E$80,Step1_Features!D$4:D$80) -> -2430.1037 | C5: =SUMPRODUCT(Step1_Features!E$4:E$80,Step1_Features!E$4:E$80) -> 142411.49 | D5: =SUMPRODUCT(Step1_Features!E$4:E$80,Step1_Features!F$4:F$80) -> -75926.702 | E5: =SUMPRODUCT(Step1_Features!E$4:E$80,Step1_Features!G$4:G$80) -> -10013125 | F5: =SUMPRODUCT(Step1_Features!E$4:E$80,Step1_Features!H$4:H$80) -> 4112372.5 | G5: =SUMPRODUCT(Step1_Features!E$4:E$80,Step1_Features!I$4:I$80) -> -4112372.5 | H5: =SUMPRODUCT(Step1_Features!E$4:E$80,Step1_Features!J$4:J$80) -> 7.781294e+08 | I5: =SUMPRODUCT(Step1_Features!E$4:E$80,Step1_Features!K$4:K$80) -> -2.6400168e+08 | J5: =SUMPRODUCT(Step1_Features!E$4:E$80,Step1_Features!L$4:L$80) -> 2.1221711e+08 | K5: =SUMPRODUCT(Step1_Features!E$4:E$80,Step1_Features!M$4:M$80) -> -2.6400168e+08 | L5: =SUMPRODUCT(Step1_Features!E$4:E$80,Step1_Features!N$4:N$80) -> -6.4333891e+10 | M5: =SUMPRODUCT(Step1_Features!E$4:E$80,Step1_Features!O$4:O$80) -> 1.8809254e+10 | N5: =SUMPRODUCT(Step1_Features!E$4:E$80,Step1_Features!P$4:P$80) -> -1.2917933e+10 | O5: =SUMPRODUCT(Step1_Features!E$4:E$80,Step1_Features!Q$4:Q$80) -> 1.2917933e+10 | P5: =SUMPRODUCT(Step1_Features!E$4:E$80,Step1_Features!R$4:R$80) -> -1.8809254e+10
A6: Iq | B6: =SUMPRODUCT(Step1_Features!F$4:F$80,Step1_Features!D$4:D$80) -> 2430.1037 | C6: =SUMPRODUCT(Step1_Features!F$4:F$80,Step1_Features!E$4:E$80) -> -75926.702 | D6: =SUMPRODUCT(Step1_Features!F$4:F$80,Step1_Features!F$4:F$80) -> 142411.49 | E6: =SUMPRODUCT(Step1_Features!F$4:F$80,Step1_Features!G$4:G$80) -> 4112372.5 | F6: =SUMPRODUCT(Step1_Features!F$4:F$80,Step1_Features!H$4:H$80) -> -4112372.5 | G6: =SUMPRODUCT(Step1_Features!F$4:F$80,Step1_Features!I$4:I$80) -> 10013125 | H6: =SUMPRODUCT(Step1_Features!F$4:F$80,Step1_Features!J$4:J$80) -> -2.6400168e+08 | I6: =SUMPRODUCT(Step1_Features!F$4:F$80,Step1_Features!K$4:K$80) -> 2.1221711e+08 | J6: =SUMPRODUCT(Step1_Features!F$4:F$80,Step1_Features!L$4:L$80) -> -2.6400168e+08 | K6: =SUMPRODUCT(Step1_Features!F$4:F$80,Step1_Features!M$4:M$80) -> 7.781294e+08 | L6: =SUMPRODUCT(Step1_Features!F$4:F$80,Step1_Features!N$4:N$80) -> 1.8809254e+10 | M6: =SUMPRODUCT(Step1_Features!F$4:F$80,Step1_Features!O$4:O$80) -> -1.2917933e+10 | N6: =SUMPRODUCT(Step1_Features!F$4:F$80,Step1_Features!P$4:P$80) -> 1.2917933e+10 | O6: =SUMPRODUCT(Step1_Features!F$4:F$80,Step1_Features!Q$4:Q$80) -> -1.8809254e+10 | P6: =SUMPRODUCT(Step1_Features!F$4:F$80,Step1_Features!R$4:R$80) -> 6.4333891e+10
A7: Id² | B7: =SUMPRODUCT(Step1_Features!G$4:G$80,Step1_Features!D$4:D$80) -> 142411.49 | C7: =SUMPRODUCT(Step1_Features!G$4:G$80,Step1_Features!E$4:E$80) -> -10013125 | D7: =SUMPRODUCT(Step1_Features!G$4:G$80,Step1_Features!F$4:F$80) -> 4112372.5 | E7: =SUMPRODUCT(Step1_Features!G$4:G$80,Step1_Features!G$4:G$80) -> 7.781294e+08 | F7: =SUMPRODUCT(Step1_Features!G$4:G$80,Step1_Features!H$4:H$80) -> -2.6400168e+08 | G7: =SUMPRODUCT(Step1_Features!G$4:G$80,Step1_Features!I$4:I$80) -> 2.1221711e+08 | H7: =SUMPRODUCT(Step1_Features!G$4:G$80,Step1_Features!J$4:J$80) -> -6.4333891e+10 | I7: =SUMPRODUCT(Step1_Features!G$4:G$80,Step1_Features!K$4:K$80) -> 1.8809254e+10 | J7: =SUMPRODUCT(Step1_Features!G$4:G$80,Step1_Features!L$4:L$80) -> -1.2917933e+10 | K7: =SUMPRODUCT(Step1_Features!G$4:G$80,Step1_Features!M$4:M$80) -> 1.2917933e+10 | L7: =SUMPRODUCT(Step1_Features!G$4:G$80,Step1_Features!N$4:N$80) -> 5.5466092e+12 | M7: =SUMPRODUCT(Step1_Features!G$4:G$80,Step1_Features!O$4:O$80) -> -1.4348388e+12 | N7: =SUMPRODUCT(Step1_Features!G$4:G$80,Step1_Features!P$4:P$80) -> 8.7578042e+11 | O7: =SUMPRODUCT(Step1_Features!G$4:G$80,Step1_Features!Q$4:Q$80) -> -7.4413256e+11 | P7: =SUMPRODUCT(Step1_Features!G$4:G$80,Step1_Features!R$4:R$80) -> 8.7578042e+11
A8: Id·Iq | B8: =SUMPRODUCT(Step1_Features!H$4:H$80,Step1_Features!D$4:D$80) -> -75926.702 | C8: =SUMPRODUCT(Step1_Features!H$4:H$80,Step1_Features!E$4:E$80) -> 4112372.5 | D8: =SUMPRODUCT(Step1_Features!H$4:H$80,Step1_Features!F$4:F$80) -> -4112372.5 | E8: =SUMPRODUCT(Step1_Features!H$4:H$80,Step1_Features!G$4:G$80) -> -2.6400168e+08 | F8: =SUMPRODUCT(Step1_Features!H$4:H$80,Step1_Features!H$4:H$80) -> 2.1221711e+08 | G8: =SUMPRODUCT(Step1_Features!H$4:H$80,Step1_Features!I$4:I$80) -> -2.6400168e+08 | H8: =SUMPRODUCT(Step1_Features!H$4:H$80,Step1_Features!J$4:J$80) -> 1.8809254e+10 | I8: =SUMPRODUCT(Step1_Features!H$4:H$80,Step1_Features!K$4:K$80) -> -1.2917933e+10 | J8: =SUMPRODUCT(Step1_Features!H$4:H$80,Step1_Features!L$4:L$80) -> 1.2917933e+10 | K8: =SUMPRODUCT(Step1_Features!H$4:H$80,Step1_Features!M$4:M$80) -> -1.8809254e+10 | L8: =SUMPRODUCT(Step1_Features!H$4:H$80,Step1_Features!N$4:N$80) -> -1.4348388e+12 | M8: =SUMPRODUCT(Step1_Features!H$4:H$80,Step1_Features!O$4:O$80) -> 8.7578042e+11 | N8: =SUMPRODUCT(Step1_Features!H$4:H$80,Step1_Features!P$4:P$80) -> -7.4413256e+11 | O8: =SUMPRODUCT(Step1_Features!H$4:H$80,Step1_Features!Q$4:Q$80) -> 8.7578042e+11 | P8: =SUMPRODUCT(Step1_Features!H$4:H$80,Step1_Features!R$4:R$80) -> -1.4348388e+12
A9: Iq² | B9: =SUMPRODUCT(Step1_Features!I$4:I$80,Step1_Features!D$4:D$80) -> 142411.49 | C9: =SUMPRODUCT(Step1_Features!I$4:I$80,Step1_Features!E$4:E$80) -> -4112372.5 | D9: =SUMPRODUCT(Step1_Features!I$4:I$80,Step1_Features!F$4:F$80) -> 10013125 | E9: =SUMPRODUCT(Step1_Features!I$4:I$80,Step1_Features!G$4:G$80) -> 2.1221711e+08 | F9: =SUMPRODUCT(Step1_Features!I$4:I$80,Step1_Features!H$4:H$80) -> -2.6400168e+08 | G9: =SUMPRODUCT(Step1_Features!I$4:I$80,Step1_Features!I$4:I$80) -> 7.781294e+08 | H9: =SUMPRODUCT(Step1_Features!I$4:I$80,Step1_Features!J$4:J$80) -> -1.2917933e+10 | I9: =SUMPRODUCT(Step1_Features!I$4:I$80,Step1_Features!K$4:K$80) -> 1.2917933e+10 | J9: =SUMPRODUCT(Step1_Features!I$4:I$80,Step1_Features!L$4:L$80) -> -1.8809254e+10 | K9: =SUMPRODUCT(Step1_Features!I$4:I$80,Step1_Features!M$4:M$80) -> 6.4333891e+10 | L9: =SUMPRODUCT(Step1_Features!I$4:I$80,Step1_Features!N$4:N$80) -> 8.7578042e+11 | M9: =SUMPRODUCT(Step1_Features!I$4:I$80,Step1_Features!O$4:O$80) -> -7.4413256e+11 | N9: =SUMPRODUCT(Step1_Features!I$4:I$80,Step1_Features!P$4:P$80) -> 8.7578042e+11 | O9: =SUMPRODUCT(Step1_Features!I$4:I$80,Step1_Features!Q$4:Q$80) -> -1.4348388e+12 | P9: =SUMPRODUCT(Step1_Features!I$4:I$80,Step1_Features!R$4:R$80) -> 5.5466092e+12
A10: Id³ | B10: =SUMPRODUCT(Step1_Features!J$4:J$80,Step1_Features!D$4:D$80) -> -10013125 | C10: =SUMPRODUCT(Step1_Features!J$4:J$80,Step1_Features!E$4:E$80) -> 7.781294e+08 | D10: =SUMPRODUCT(Step1_Features!J$4:J$80,Step1_Features!F$4:F$80) -> -2.6400168e+08 | E10: =SUMPRODUCT(Step1_Features!J$4:J$80,Step1_Features!G$4:G$80) -> -6.4333891e+10 | F10: =SUMPRODUCT(Step1_Features!J$4:J$80,Step1_Features!H$4:H$80) -> 1.8809254e+10 | G10: =SUMPRODUCT(Step1_Features!J$4:J$80,Step1_Features!I$4:I$80) -> -1.2917933e+10 | H10: =SUMPRODUCT(Step1_Features!J$4:J$80,Step1_Features!J$4:J$80) -> 5.5466092e+12 | I10: =SUMPRODUCT(Step1_Features!J$4:J$80,Step1_Features!K$4:K$80) -> -1.4348388e+12 | J10: =SUMPRODUCT(Step1_Features!J$4:J$80,Step1_Features!L$4:L$80) -> 8.7578042e+11 | K10: =SUMPRODUCT(Step1_Features!J$4:J$80,Step1_Features!M$4:M$80) -> -7.4413256e+11 | L10: =SUMPRODUCT(Step1_Features!J$4:J$80,Step1_Features!N$4:N$80) -> -4.9283974e+14 | M10: =SUMPRODUCT(Step1_Features!J$4:J$80,Step1_Features!O$4:O$80) -> 1.1483294e+14 | N10: =SUMPRODUCT(Step1_Features!J$4:J$80,Step1_Features!P$4:P$80) -> -63854166014521 | O10: =SUMPRODUCT(Step1_Features!J$4:J$80,Step1_Features!Q$4:Q$80) -> 4.7927264e+13 | P10: =SUMPRODUCT(Step1_Features!J$4:J$80,Step1_Features!R$4:R$80) -> -4.7927264e+13
A11: Id²·Iq | B11: =SUMPRODUCT(Step1_Features!K$4:K$80,Step1_Features!D$4:D$80) -> 4112372.5 | C11: =SUMPRODUCT(Step1_Features!K$4:K$80,Step1_Features!E$4:E$80) -> -2.6400168e+08 | D11: =SUMPRODUCT(Step1_Features!K$4:K$80,Step1_Features!F$4:F$80) -> 2.1221711e+08 | E11: =SUMPRODUCT(Step1_Features!K$4:K$80,Step1_Features!G$4:G$80) -> 1.8809254e+10 | F11: =SUMPRODUCT(Step1_Features!K$4:K$80,Step1_Features!H$4:H$80) -> -1.2917933e+10 | G11: =SUMPRODUCT(Step1_Features!K$4:K$80,Step1_Features!I$4:I$80) -> 1.2917933e+10 | H11: =SUMPRODUCT(Step1_Features!K$4:K$80,Step1_Features!J$4:J$80) -> -1.4348388e+12 | I11: =SUMPRODUCT(Step1_Features!K$4:K$80,Step1_Features!K$4:K$80) -> 8.7578042e+11 | J11: =SUMPRODUCT(Step1_Features!K$4:K$80,Step1_Features!L$4:L$80) -> -7.4413256e+11 | K11: =SUMPRODUCT(Step1_Features!K$4:K$80,Step1_Features!M$4:M$80) -> 8.7578042e+11 | L11: =SUMPRODUCT(Step1_Features!K$4:K$80,Step1_Features!N$4:N$80) -> 1.1483294e+14 | M11: =SUMPRODUCT(Step1_Features!K$4:K$80,Step1_Features!O$4:O$80) -> -63854166014521 | N11: =SUMPRODUCT(Step1_Features!K$4:K$80,Step1_Features!P$4:P$80) -> 4.7927264e+13 | O11: =SUMPRODUCT(Step1_Features!K$4:K$80,Step1_Features!Q$4:Q$80) -> -4.7927264e+13 | P11: =SUMPRODUCT(Step1_Features!K$4:K$80,Step1_Features!R$4:R$80) -> 6.3854166e+13
A12: Id·Iq² | B12: =SUMPRODUCT(Step1_Features!L$4:L$80,Step1_Features!D$4:D$80) -> -4112372.5 | C12: =SUMPRODUCT(Step1_Features!L$4:L$80,Step1_Features!E$4:E$80) -> 2.1221711e+08 | D12: =SUMPRODUCT(Step1_Features!L$4:L$80,Step1_Features!F$4:F$80) -> -2.6400168e+08 | E12: =SUMPRODUCT(Step1_Features!L$4:L$80,Step1_Features!G$4:G$80) -> -1.2917933e+10 | F12: =SUMPRODUCT(Step1_Features!L$4:L$80,Step1_Features!H$4:H$80) -> 1.2917933e+10 | G12: =SUMPRODUCT(Step1_Features!L$4:L$80,Step1_Features!I$4:I$80) -> -1.8809254e+10 | H12: =SUMPRODUCT(Step1_Features!L$4:L$80,Step1_Features!J$4:J$80) -> 8.7578042e+11 | I12: =SUMPRODUCT(Step1_Features!L$4:L$80,Step1_Features!K$4:K$80) -> -7.4413256e+11 | J12: =SUMPRODUCT(Step1_Features!L$4:L$80,Step1_Features!L$4:L$80) -> 8.7578042e+11 | K12: =SUMPRODUCT(Step1_Features!L$4:L$80,Step1_Features!M$4:M$80) -> -1.4348388e+12 | L12: =SUMPRODUCT(Step1_Features!L$4:L$80,Step1_Features!N$4:N$80) -> -6.3854166e+13 | M12: =SUMPRODUCT(Step1_Features!L$4:L$80,Step1_Features!O$4:O$80) -> 4.7927264e+13 | N12: =SUMPRODUCT(Step1_Features!L$4:L$80,Step1_Features!P$4:P$80) -> -4.7927264e+13 | O12: =SUMPRODUCT(Step1_Features!L$4:L$80,Step1_Features!Q$4:Q$80) -> 6.3854166e+13 | P12: =SUMPRODUCT(Step1_Features!L$4:L$80,Step1_Features!R$4:R$80) -> -1.1483294e+14
A13: Iq³ | B13: =SUMPRODUCT(Step1_Features!M$4:M$80,Step1_Features!D$4:D$80) -> 10013125 | C13: =SUMPRODUCT(Step1_Features!M$4:M$80,Step1_Features!E$4:E$80) -> -2.6400168e+08 | D13: =SUMPRODUCT(Step1_Features!M$4:M$80,Step1_Features!F$4:F$80) -> 7.781294e+08 | E13: =SUMPRODUCT(Step1_Features!M$4:M$80,Step1_Features!G$4:G$80) -> 1.2917933e+10 | F13: =SUMPRODUCT(Step1_Features!M$4:M$80,Step1_Features!H$4:H$80) -> -1.8809254e+10 | G13: =SUMPRODUCT(Step1_Features!M$4:M$80,Step1_Features!I$4:I$80) -> 6.4333891e+10 | H13: =SUMPRODUCT(Step1_Features!M$4:M$80,Step1_Features!J$4:J$80) -> -7.4413256e+11 | I13: =SUMPRODUCT(Step1_Features!M$4:M$80,Step1_Features!K$4:K$80) -> 8.7578042e+11 | J13: =SUMPRODUCT(Step1_Features!M$4:M$80,Step1_Features!L$4:L$80) -> -1.4348388e+12 | K13: =SUMPRODUCT(Step1_Features!M$4:M$80,Step1_Features!M$4:M$80) -> 5.5466092e+12 | L13: =SUMPRODUCT(Step1_Features!M$4:M$80,Step1_Features!N$4:N$80) -> 4.7927264e+13 | M13: =SUMPRODUCT(Step1_Features!M$4:M$80,Step1_Features!O$4:O$80) -> -4.7927264e+13 | N13: =SUMPRODUCT(Step1_Features!M$4:M$80,Step1_Features!P$4:P$80) -> 6.3854166e+13 | O13: =SUMPRODUCT(Step1_Features!M$4:M$80,Step1_Features!Q$4:Q$80) -> -1.1483294e+14 | P13: =SUMPRODUCT(Step1_Features!M$4:M$80,Step1_Features!R$4:R$80) -> 4.9283974e+14
A14: Id⁴ | B14: =SUMPRODUCT(Step1_Features!N$4:N$80,Step1_Features!D$4:D$80) -> 7.781294e+08 | C14: =SUMPRODUCT(Step1_Features!N$4:N$80,Step1_Features!E$4:E$80) -> -6.4333891e+10 | D14: =SUMPRODUCT(Step1_Features!N$4:N$80,Step1_Features!F$4:F$80) -> 1.8809254e+10 | E14: =SUMPRODUCT(Step1_Features!N$4:N$80,Step1_Features!G$4:G$80) -> 5.5466092e+12 | F14: =SUMPRODUCT(Step1_Features!N$4:N$80,Step1_Features!H$4:H$80) -> -1.4348388e+12 | G14: =SUMPRODUCT(Step1_Features!N$4:N$80,Step1_Features!I$4:I$80) -> 8.7578042e+11 | H14: =SUMPRODUCT(Step1_Features!N$4:N$80,Step1_Features!J$4:J$80) -> -4.9283974e+14 | I14: =SUMPRODUCT(Step1_Features!N$4:N$80,Step1_Features!K$4:K$80) -> 1.1483294e+14 | J14: =SUMPRODUCT(Step1_Features!N$4:N$80,Step1_Features!L$4:L$80) -> -6.3854166e+13 | K14: =SUMPRODUCT(Step1_Features!N$4:N$80,Step1_Features!M$4:M$80) -> 4.7927264e+13 | L14: =SUMPRODUCT(Step1_Features!N$4:N$80,Step1_Features!N$4:N$80) -> 4.4793995e+16 | M14: =SUMPRODUCT(Step1_Features!N$4:N$80,Step1_Features!O$4:O$80) -> -9.5226005e+15 | N14: =SUMPRODUCT(Step1_Features!N$4:N$80,Step1_Features!P$4:P$80) -> 4.9044522e+15 | O14: =SUMPRODUCT(Step1_Features!N$4:N$80,Step1_Features!Q$4:Q$80) -> -3.3337695e+15 | P14: =SUMPRODUCT(Step1_Features!N$4:N$80,Step1_Features!R$4:R$80) -> 2.9426713e+15
A15: Id³·Iq | B15: =SUMPRODUCT(Step1_Features!O$4:O$80,Step1_Features!D$4:D$80) -> -2.6400168e+08 | C15: =SUMPRODUCT(Step1_Features!O$4:O$80,Step1_Features!E$4:E$80) -> 1.8809254e+10 | D15: =SUMPRODUCT(Step1_Features!O$4:O$80,Step1_Features!F$4:F$80) -> -1.2917933e+10 | E15: =SUMPRODUCT(Step1_Features!O$4:O$80,Step1_Features!G$4:G$80) -> -1.4348388e+12 | F15: =SUMPRODUCT(Step1_Features!O$4:O$80,Step1_Features!H$4:H$80) -> 8.7578042e+11 | G15: =SUMPRODUCT(Step1_Features!O$4:O$80,Step1_Features!I$4:I$80) -> -7.4413256e+11 | H15: =SUMPRODUCT(Step1_Features!O$4:O$80,Step1_Features!J$4:J$80) -> 1.1483294e+14 | I15: =SUMPRODUCT(Step1_Features!O$4:O$80,Step1_Features!K$4:K$80) -> -63854166014521 | J15: =SUMPRODUCT(Step1_Features!O$4:O$80,Step1_Features!L$4:L$80) -> 4.7927264e+13 | K15: =SUMPRODUCT(Step1_Features!O$4:O$80,Step1_Features!M$4:M$80) -> -4.7927264e+13 | L15: =SUMPRODUCT(Step1_Features!O$4:O$80,Step1_Features!N$4:N$80) -> -9.5226005e+15 | M15: =SUMPRODUCT(Step1_Features!O$4:O$80,Step1_Features!O$4:O$80) -> 4.9044522e+15 | N15: =SUMPRODUCT(Step1_Features!O$4:O$80,Step1_Features!P$4:P$80) -> -3.3337695e+15 | O15: =SUMPRODUCT(Step1_Features!O$4:O$80,Step1_Features!Q$4:Q$80) -> 2.9426713e+15 | P15: =SUMPRODUCT(Step1_Features!O$4:O$80,Step1_Features!R$4:R$80) -> -3.3337695e+15
A16: Id²·Iq² | B16: =SUMPRODUCT(Step1_Features!P$4:P$80,Step1_Features!D$4:D$80) -> 2.1221711e+08 | C16: =SUMPRODUCT(Step1_Features!P$4:P$80,Step1_Features!E$4:E$80) -> -1.2917933e+10 | D16: =SUMPRODUCT(Step1_Features!P$4:P$80,Step1_Features!F$4:F$80) -> 1.2917933e+10 | E16: =SUMPRODUCT(Step1_Features!P$4:P$80,Step1_Features!G$4:G$80) -> 8.7578042e+11 | F16: =SUMPRODUCT(Step1_Features!P$4:P$80,Step1_Features!H$4:H$80) -> -7.4413256e+11 | G16: =SUMPRODUCT(Step1_Features!P$4:P$80,Step1_Features!I$4:I$80) -> 8.7578042e+11 | H16: =SUMPRODUCT(Step1_Features!P$4:P$80,Step1_Features!J$4:J$80) -> -63854166014521 | I16: =SUMPRODUCT(Step1_Features!P$4:P$80,Step1_Features!K$4:K$80) -> 4.7927264e+13 | J16: =SUMPRODUCT(Step1_Features!P$4:P$80,Step1_Features!L$4:L$80) -> -4.7927264e+13 | K16: =SUMPRODUCT(Step1_Features!P$4:P$80,Step1_Features!M$4:M$80) -> 6.3854166e+13 | L16: =SUMPRODUCT(Step1_Features!P$4:P$80,Step1_Features!N$4:N$80) -> 4.9044522e+15 | M16: =SUMPRODUCT(Step1_Features!P$4:P$80,Step1_Features!O$4:O$80) -> -3.3337695e+15 | N16: =SUMPRODUCT(Step1_Features!P$4:P$80,Step1_Features!P$4:P$80) -> 2.9426713e+15 | O16: =SUMPRODUCT(Step1_Features!P$4:P$80,Step1_Features!Q$4:Q$80) -> -3.3337695e+15 | P16: =SUMPRODUCT(Step1_Features!P$4:P$80,Step1_Features!R$4:R$80) -> 4.9044522e+15
A17: Id·Iq³ | B17: =SUMPRODUCT(Step1_Features!Q$4:Q$80,Step1_Features!D$4:D$80) -> -2.6400168e+08 | C17: =SUMPRODUCT(Step1_Features!Q$4:Q$80,Step1_Features!E$4:E$80) -> 1.2917933e+10 | D17: =SUMPRODUCT(Step1_Features!Q$4:Q$80,Step1_Features!F$4:F$80) -> -1.8809254e+10 | E17: =SUMPRODUCT(Step1_Features!Q$4:Q$80,Step1_Features!G$4:G$80) -> -7.4413256e+11 | F17: =SUMPRODUCT(Step1_Features!Q$4:Q$80,Step1_Features!H$4:H$80) -> 8.7578042e+11 | G17: =SUMPRODUCT(Step1_Features!Q$4:Q$80,Step1_Features!I$4:I$80) -> -1.4348388e+12 | H17: =SUMPRODUCT(Step1_Features!Q$4:Q$80,Step1_Features!J$4:J$80) -> 4.7927264e+13 | I17: =SUMPRODUCT(Step1_Features!Q$4:Q$80,Step1_Features!K$4:K$80) -> -4.7927264e+13 | J17: =SUMPRODUCT(Step1_Features!Q$4:Q$80,Step1_Features!L$4:L$80) -> 6.3854166e+13 | K17: =SUMPRODUCT(Step1_Features!Q$4:Q$80,Step1_Features!M$4:M$80) -> -1.1483294e+14 | L17: =SUMPRODUCT(Step1_Features!Q$4:Q$80,Step1_Features!N$4:N$80) -> -3.3337695e+15 | M17: =SUMPRODUCT(Step1_Features!Q$4:Q$80,Step1_Features!O$4:O$80) -> 2.9426713e+15 | N17: =SUMPRODUCT(Step1_Features!Q$4:Q$80,Step1_Features!P$4:P$80) -> -3.3337695e+15 | O17: =SUMPRODUCT(Step1_Features!Q$4:Q$80,Step1_Features!Q$4:Q$80) -> 4.9044522e+15 | P17: =SUMPRODUCT(Step1_Features!Q$4:Q$80,Step1_Features!R$4:R$80) -> -9.5226005e+15
A18: Iq⁴ | B18: =SUMPRODUCT(Step1_Features!R$4:R$80,Step1_Features!D$4:D$80) -> 7.781294e+08 | C18: =SUMPRODUCT(Step1_Features!R$4:R$80,Step1_Features!E$4:E$80) -> -1.8809254e+10 | D18: =SUMPRODUCT(Step1_Features!R$4:R$80,Step1_Features!F$4:F$80) -> 6.4333891e+10 | E18: =SUMPRODUCT(Step1_Features!R$4:R$80,Step1_Features!G$4:G$80) -> 8.7578042e+11 | F18: =SUMPRODUCT(Step1_Features!R$4:R$80,Step1_Features!H$4:H$80) -> -1.4348388e+12 | G18: =SUMPRODUCT(Step1_Features!R$4:R$80,Step1_Features!I$4:I$80) -> 5.5466092e+12 | H18: =SUMPRODUCT(Step1_Features!R$4:R$80,Step1_Features!J$4:J$80) -> -4.7927264e+13 | I18: =SUMPRODUCT(Step1_Features!R$4:R$80,Step1_Features!K$4:K$80) -> 6.3854166e+13 | J18: =SUMPRODUCT(Step1_Features!R$4:R$80,Step1_Features!L$4:L$80) -> -1.1483294e+14 | K18: =SUMPRODUCT(Step1_Features!R$4:R$80,Step1_Features!M$4:M$80) -> 4.9283974e+14 | L18: =SUMPRODUCT(Step1_Features!R$4:R$80,Step1_Features!N$4:N$80) -> 2.9426713e+15 | M18: =SUMPRODUCT(Step1_Features!R$4:R$80,Step1_Features!O$4:O$80) -> -3.3337695e+15 | N18: =SUMPRODUCT(Step1_Features!R$4:R$80,Step1_Features!P$4:P$80) -> 4.9044522e+15 | O18: =SUMPRODUCT(Step1_Features!R$4:R$80,Step1_Features!Q$4:Q$80) -> -9.5226005e+15 | P18: =SUMPRODUCT(Step1_Features!R$4:R$80,Step1_Features!R$4:R$80) -> 4.4793995e+16
A21: Xᵀy vector (15×1) — SUMPRODUCT of each feature column with measured Ld
A22: Feature | B22: XᵀLd (=SUMPRODUCT(feature col, Ld col)) | C22: Formula shown explicitly
A23: 1 (constant) | B23: =SUMPRODUCT(Step1_Features!D$4:D$80,Raw_Data!D$3:D$79) -> 37807.932 | C23: SUMPRODUCT( Step1_Features col D × Raw_Data col D ) — rows 3:79
A24: Id | B24: =SUMPRODUCT(Step1_Features!E$4:E$80,Raw_Data!D$3:D$79) -> -1197939.6 | C24: SUMPRODUCT( Step1_Features col E × Raw_Data col D ) — rows 3:79
A25: Iq | B25: =SUMPRODUCT(Step1_Features!F$4:F$80,Raw_Data!D$3:D$79) -> 1166436.5 | C25: SUMPRODUCT( Step1_Features col F × Raw_Data col D ) — rows 3:79
A26: Id² | B26: =SUMPRODUCT(Step1_Features!G$4:G$80,Raw_Data!D$3:D$79) -> 70233039 | C26: SUMPRODUCT( Step1_Features col G × Raw_Data col D ) — rows 3:79
A27: Id·Iq | B27: =SUMPRODUCT(Step1_Features!H$4:H$80,Raw_Data!D$3:D$79) -> -37021143 | C27: SUMPRODUCT( Step1_Features col H × Raw_Data col D ) — rows 3:79
A28: Iq² | B28: =SUMPRODUCT(Step1_Features!I$4:I$80,Raw_Data!D$3:D$79) -> 67376973 | C28: SUMPRODUCT( Step1_Features col I × Raw_Data col D ) — rows 3:79
A29: Id³ | B29: =SUMPRODUCT(Step1_Features!J$4:J$80,Raw_Data!D$3:D$79) -> -4.9401248e+09 | C29: SUMPRODUCT( Step1_Features col J × Raw_Data col D ) — rows 3:79
A30: Id²·Iq | B30: =SUMPRODUCT(Step1_Features!K$4:K$80,Raw_Data!D$3:D$79) -> 2.0111981e+09 | C30: SUMPRODUCT( Step1_Features col K × Raw_Data col D ) — rows 3:79
A31: Id·Iq² | B31: =SUMPRODUCT(Step1_Features!L$4:L$80,Raw_Data!D$3:D$79) -> -1.9899672e+09 | C31: SUMPRODUCT( Step1_Features col L × Raw_Data col D ) — rows 3:79
A32: Iq³ | B32: =SUMPRODUCT(Step1_Features!M$4:M$80,Raw_Data!D$3:D$79) -> 4.6854724e+09 | C32: SUMPRODUCT( Step1_Features col M × Raw_Data col D ) — rows 3:79
A33: Id⁴ | B33: =SUMPRODUCT(Step1_Features!N$4:N$80,Raw_Data!D$3:D$79) -> 3.8400086e+11 | C33: SUMPRODUCT( Step1_Features col N × Raw_Data col D ) — rows 3:79
A34: Id³·Iq | B34: =SUMPRODUCT(Step1_Features!O$4:O$80,Raw_Data!D$3:D$79) -> -1.2938567e+11 | C34: SUMPRODUCT( Step1_Features col O × Raw_Data col D ) — rows 3:79
A35: Id²·Iq² | B35: =SUMPRODUCT(Step1_Features!P$4:P$80,Raw_Data!D$3:D$79) -> 1.0317842e+11 | C35: SUMPRODUCT( Step1_Features col P × Raw_Data col D ) — rows 3:79
A36: Id·Iq³ | B36: =SUMPRODUCT(Step1_Features!Q$4:Q$80,Raw_Data!D$3:D$79) -> -1.2693585e+11 | C36: SUMPRODUCT( Step1_Features col Q × Raw_Data col D ) — rows 3:79
A37: Iq⁴ | B37: =SUMPRODUCT(Step1_Features!R$4:R$80,Raw_Data!D$3:D$79) -> 3.6097703e+11 | C37: SUMPRODUCT( Step1_Features col R × Raw_Data col D ) — rows 3:79

Sheet Step3_Ld_Coefs
A1: Step 3 — Ld Coefficients β via MMULT(MINVERSE(XᵀX), Xᵀy)
A2: β = (XᵀX)⁻¹ · Xᵀy | Col D: each β from MMULT/MINVERSE referencing Step2 | Col F: feature value at example | Col G = D × F
A3: # | B3: Feature | C3: Excel expression (A=Id, B=Iq) | D3: β coefficient | E3: Physical meaning | F3: Feature value at Id=−30,Iq=20 | G3: Contribution (β × feature)
A4: 0 | B4: 1 (constant) | C4: 1 | D4: =INDEX(MMULT(MINVERSE(Step2_Ld_XtX!$B$4:$P$18),Step2_Ld_XtX!$B$23:$B$37),1,1) -> 500.41551 | E4: Baseline value at zero current | F4: =1 -> 1 | G4: =D4*F4 -> 500.41551
A5: 1 | B5: Id | C5: A | D5: =INDEX(MMULT(MINVERSE(Step2_Ld_XtX!$B$4:$P$18),Step2_Ld_XtX!$B$23:$B$37),2,1) -> -0.17118854 | E5: Linear sensitivity to d-axis current | F5: =-30 -> -30 | G5: =D5*F5 -> 5.1356562
A6: 2 | B6: Iq | C6: B | D6: =INDEX(MMULT(MINVERSE(Step2_Ld_XtX!$B$4:$P$18),Step2_Ld_XtX!$B$23:$B$37),3,1) -> 0.07899178 | E6: Linear sensitivity to q-axis current | F6: =20 -> 20 | G6: =D6*F6 -> 1.5798356
A7: 3 | B7: Id² | C7: A^2 | D7: =INDEX(MMULT(MINVERSE(Step2_Ld_XtX!$B$4:$P$18),Step2_Ld_XtX!$B$23:$B$37),4,1) -> -0.0079838517 | E7: Quadratic self-saturation — Id | F7: =(-30)^2 -> 900 | G7: =D7*F7 -> -7.1854665
A8: 4 | B8: Id·Iq | C8: A*B | D8: =INDEX(MMULT(MINVERSE(Step2_Ld_XtX!$B$4:$P$18),Step2_Ld_XtX!$B$23:$B$37),5,1) -> -0.0078011761 | E8: Cross-saturation (Id × Iq) | F8: =(-30)*20 -> -600 | G8: =D8*F8 -> 4.6807057
A9: 5 | B9: Iq² | C9: B^2 | D9: =INDEX(MMULT(MINVERSE(Step2_Ld_XtX!$B$4:$P$18),Step2_Ld_XtX!$B$23:$B$37),6,1) -> -0.018291945 | E9: Quadratic self-saturation — Iq | F9: =20^2 -> 400 | G9: =D9*F9 -> -7.3167778
A10: 6 | B10: Id³ | C10: A^3 | D10: =INDEX(MMULT(MINVERSE(Step2_Ld_XtX!$B$4:$P$18),Step2_Ld_XtX!$B$23:$B$37),7,1) -> -9.3273657e-05 | E10: Cubic correction — Id | F10: =(-30)^3 -> -27000 | G10: =D10*F10 -> 2.5183887
A11: 7 | B11: Id²·Iq | C11: A^2*B | D11: =INDEX(MMULT(MINVERSE(Step2_Ld_XtX!$B$4:$P$18),Step2_Ld_XtX!$B$23:$B$37),8,1) -> -0.00014440794 | E11: Cubic cross-term Id²·Iq | F11: =(-30)^2*20 -> 18000 | G11: =D11*F11 -> -2.599343
A12: 8 | B12: Id·Iq² | C12: A*B^2 | D12: =INDEX(MMULT(MINVERSE(Step2_Ld_XtX!$B$4:$P$18),Step2_Ld_XtX!$B$23:$B$37),9,1) -> -0.0001209361 | E12: Cubic cross-term Id·Iq² | F12: =(-30)*20^2 -> -12000 | G12: =D12*F12 -> 1.4512332
A13: 9 | B13: Iq³ | C13: B^3 | D13: =INDEX(MMULT(MINVERSE(Step2_Ld_XtX!$B$4:$P$18),Step2_Ld_XtX!$B$23:$B$37),10,1) -> 0.00020428917 | E13: Cubic correction — Iq | F13: =20^3 -> 8000 | G13: =D13*F13 -> 1.6343133
A14: 10 | B14: Id⁴ | C14: A^4 | D14: =INDEX(MMULT(MINVERSE(Step2_Ld_XtX!$B$4:$P$18),Step2_Ld_XtX!$B$23:$B$37),11,1) -> -3.6270832e-07 | E14: 4th-order correction — Id | F14: =(-30)^4 -> 810000 | G14: =D14*F14 -> -0.29379374
A15: 11 | B15: Id³·Iq | C15: A^3*B | D15: =INDEX(MMULT(MINVERSE(Step2_Ld_XtX!$B$4:$P$18),Step2_Ld_XtX!$B$23:$B$37),12,1) -> -5.7514288e-07 | E15: 4th-order cross-term Id³·Iq | F15: =(-30)^3*20 -> -540000 | G15: =D15*F15 -> 0.31057715
A16: 12 | B16: Id²·Iq² | C16: A^2*B^2 | D16: =INDEX(MMULT(MINVERSE(Step2_Ld_XtX!$B$4:$P$18),Step2_Ld_XtX!$B$23:$B$37),13,1) -> 1.3937826e-07 | E16: 4th-order cross-term Id²·Iq² | F16: =(-30)^2*20^2 -> 360000 | G16: =D16*F16 -> 0.050176174
A17: 13 | B17: Id·Iq³ | C17: A*B^3 | D17: =INDEX(MMULT(MINVERSE(Step2_Ld_XtX!$B$4:$P$18),Step2_Ld_XtX!$B$23:$B$37),14,1) -> 8.3138155e-07 | E17: 4th-order cross-term Id·Iq³ | F17: =(-30)*20^3 -> -240000 | G17: =D17*F17 -> -0.19953157
A18: 14 | B18: Iq⁴ | C18: B^4 | D18: =INDEX(MMULT(MINVERSE(Step2_Ld_XtX!$B$4:$P$18),Step2_Ld_XtX!$B$23:$B$37),15,1) -> -9.5751922e-07 | E18: 4th-order correction — Iq | F18: =20^4 -> 160000 | G18: =D18*F18 -> -0.15320307
B19: TOTAL | G19: =SUM(G4:G18) -> 500.02828
A20: Example at Id=−30 A, Iq=20 A. Col G total = predicted value.

Sheet Step4_Ld_Preds
A1: Step 4 — Ld Predictions and Residuals (all 77 rows)
A2: Row | B2: Id_ref (A) | C2: Iq_ref (A) | D2: Actual Ld (µH) | E2: Predicted Ld (µH) | F2: Error (µH) | G2: Squared Error | H2: % Error
A3: 1 | B3: =Raw_Data!B3 -> 0 | C3: =Raw_Data!C3 -> 0 | D3: =Raw_Data!D3 -> 500.41526 | E3: =Step3_Ld_Coefs!$D$4*Step1_Features!D4+Step3_Ld_Coefs!$D$5*Step1_Features!E4+Step3_Ld_Coefs!$D$6*Step1_Features!F4+Step3_Ld_Coefs!$D$7*Step1_Features!G4+Step3_Ld_Coefs!$D$8*Step1_Features!H4+Step3_Ld_Coefs!$D$9*Step1_Features!I4+Step3_Ld_Coefs!$D$10*Step1_Features!J4+Step3_Ld_Coefs!$D$11*Step1_Features!K4+Step3_Ld_Coefs!$D$12*Step1_Features!L4+Step3_Ld_Coefs!$D$13*Step1_Features!M4+Step3_Ld_Coefs!$D$14*Step1_Features!N4+Step3_Ld_Coefs!$D$15*Step1_Features!O4+Step3_Ld_Coefs!$D$16*Step1_Features!P4+Step3_Ld_Coefs!$D$17*Step1_Features!Q4+Step3_Ld_Coefs!$D$18*Step1_Features!R4 -> 500.41551 | F3: =D3-E3 -> -0.00025210582 | G3: =F3^2 -> 6.3557342e-08 | H3: =F3/D3*100 -> -5.0379323e-05
A4: 2 | B4: =Raw_Data!B4 -> 0 | C4: =Raw_Data!C4 -> 0 | D4: =Raw_Data!D4 -> 501.00862 | E4: =Step3_Ld_Coefs!$D$4*Step1_Features!D5+Step3_Ld_Coefs!$D$5*Step1_Features!E5+Step3_Ld_Coefs!$D$6*Step1_Features!F5+Step3_Ld_Coefs!$D$7*Step1_Features!G5+Step3_Ld_Coefs!$D$8*Step1_Features!H5+Step3_Ld_Coefs!$D$9*Step1_Features!I5+Step3_Ld_Coefs!$D$10*Step1_Features!J5+Step3_Ld_Coefs!$D$11*Step1_Features!K5+Step3_Ld_Coefs!$D$12*Step1_Features!L5+Step3_Ld_Coefs!$D$13*Step1_Features!M5+Step3_Ld_Coefs!$D$14*Step1_Features!N5+Step3_Ld_Coefs!$D$15*Step1_Features!O5+Step3_Ld_Coefs!$D$16*Step1_Features!P5+Step3_Ld_Coefs!$D$17*Step1_Features!Q5+Step3_Ld_Coefs!$D$18*Step1_Features!R5 -> 500.41551 | F4: =D4-E4 -> 0.59310889 | G4: =F4^2 -> 0.35177816 | H4: =F4/D4*100 -> 0.11838297
A5: 3 | B5: =Raw_Data!B5 -> 0 | C5: =Raw_Data!C5 -> 0 | D5: =Raw_Data!D5 -> 501.26213 | E5: =Step3_Ld_Coefs!$D$4*Step1_Features!D6+Step3_Ld_Coefs!$D$5*Step1_Features!E6+Step3_Ld_Coefs!$D$6*Step1_Features!F6+Step3_Ld_Coefs!$D$7*Step1_Features!G6+Step3_Ld_Coefs!$D$8*Step1_Features!H6+Step3_Ld_Coefs!$D$9*Step1_Features!I6+Step3_Ld_Coefs!$D$10*Step1_Features!J6+Step3_Ld_Coefs!$D$11*Step1_Features!K6+Step3_Ld_Coefs!$D$12*Step1_Features!L6+Step3_Ld_Coefs!$D$13*Step1_Features!M6+Step3_Ld_Coefs!$D$14*Step1_Features!N6+Step3_Ld_Coefs!$D$15*Step1_Features!O6+Step3_Ld_Coefs!$D$16*Step1_Features!P6+Step3_Ld_Coefs!$D$17*Step1_Features!Q6+Step3_Ld_Coefs!$D$18*Step1_Features!R6 -> 500.41551 | F5: =D5-E5 -> 0.84662289 | G5: =F5^2 -> 0.71677032 | H5: =F5/D5*100 -> 0.16889824
A6: 4 | B6: =Raw_Data!B6 -> 0 | C6: =Raw_Data!C6 -> 0 | D6: =Raw_Data!D6 -> 501.10672 | E6: =Step3_Ld_Coefs!$D$4*Step1_Features!D7+Step3_Ld_Coefs!$D$5*Step1_Features!E7+Step3_Ld_Coefs!$D$6*Step1_Features!F7+Step3_Ld_Coefs!$D$7*Step1_Features!G7+Step3_Ld_Coefs!$D$8*Step1_Features!H7+Step3_Ld_Coefs!$D$9*Step1_Features!I7+Step3_Ld_Coefs!$D$10*Step1_Features!J7+Step3_Ld_Coefs!$D$11*Step1_Features!K7+Step3_Ld_Coefs!$D$12*Step1_Features!L7+Step3_Ld_Coefs!$D$13*Step1_Features!M7+Step3_Ld_Coefs!$D$14*Step1_Features!N7+Step3_Ld_Coefs!$D$15*Step1_Features!O7+Step3_Ld_Coefs!$D$16*Step1_Features!P7+Step3_Ld_Coefs!$D$17*Step1_Features!Q7+Step3_Ld_Coefs!$D$18*Step1_Features!R7 -> 500.41551 | F6: =D6-E6 -> 0.69121489 | G6: =F6^2 -> 0.47777803 | H6: =F6/D6*100 -> 0.13793766
A7: 5 | B7: =Raw_Data!B7 -> 0 | C7: =Raw_Data!C7 -> 0 | D7: =Raw_Data!D7 -> 500.58529 | E7: =Step3_Ld_Coefs!$D$4*Step1_Features!D8+Step3_Ld_Coefs!$D$5*Step1_Features!E8+Step3_Ld_Coefs!$D$6*Step1_Features!F8+Step3_Ld_Coefs!$D$7*Step1_Features!G8+Step3_Ld_Coefs!$D$8*Step1_Features!H8+Step3_Ld_Coefs!$D$9*Step1_Features!I8+Step3_Ld_Coefs!$D$10*Step1_Features!J8+Step3_Ld_Coefs!$D$11*Step1_Features!K8+Step3_Ld_Coefs!$D$12*Step1_Features!L8+Step3_Ld_Coefs!$D$13*Step1_Features!M8+Step3_Ld_Coefs!$D$14*Step1_Features!N8+Step3_Ld_Coefs!$D$15*Step1_Features!O8+Step3_Ld_Coefs!$D$16*Step1_Features!P8+Step3_Ld_Coefs!$D$17*Step1_Features!Q8+Step3_Ld_Coefs!$D$18*Step1_Features!R8 -> 500.41551 | F7: =D7-E7 -> 0.16977889 | G7: =F7^2 -> 0.028824873 | H7: =F7/D7*100 -> 0.033916078
A8: 6 | B8: =Raw_Data!B8 -> 0 | C8: =Raw_Data!C8 -> 0 | D8: =Raw_Data!D8 -> 499.83822 | E8: =Step3_Ld_Coefs!$D$4*Step1_Features!D9+Step3_Ld_Coefs!$D$5*Step1_Features!E9+Step3_Ld_Coefs!$D$6*Step1_Features!F9+Step3_Ld_Coefs!$D$7*Step1_Features!G9+Step3_Ld_Coefs!$D$8*Step1_Features!H9+Step3_Ld_Coefs!$D$9*Step1_Features!I9+Step3_Ld_Coefs!$D$10*Step1_Features!J9+Step3_Ld_Coefs!$D$11*Step1_Features!K9+Step3_Ld_Coefs!$D$12*Step1_Features!L9+Step3_Ld_Coefs!$D$13*Step1_Features!M9+Step3_Ld_Coefs!$D$14*Step1_Features!N9+Step3_Ld_Coefs!$D$15*Step1_Features!O9+Step3_Ld_Coefs!$D$16*Step1_Features!P9+Step3_Ld_Coefs!$D$17*Step1_Features!Q9+Step3_Ld_Coefs!$D$18*Step1_Features!R9 -> 500.41551 | F8: =D8-E8 -> -0.57728311 | G8: =F8^2 -> 0.33325578 | H8: =F8/D8*100 -> -0.11549399
A9: 7 | B9: =Raw_Data!B9 -> 0 | C9: =Raw_Data!C9 -> 0 | D9: =Raw_Data!D9 -> 499.06435 | E9: =Step3_Ld_Coefs!$D$4*Step1_Features!D10+Step3_Ld_Coefs!$D$5*Step1_Features!E10+Step3_Ld_Coefs!$D$6*Step1_Features!F10+Step3_Ld_Coefs!$D$7*Step1_Features!G10+Step3_Ld_Coefs!$D$8*Step1_Features!H10+Step3_Ld_Coefs!$D$9*Step1_Features!I10+Step3_Ld_Coefs!$D$10*Step1_Features!J10+Step3_Ld_Coefs!$D$11*Step1_Features!K10+Step3_Ld_Coefs!$D$12*Step1_Features!L10+Step3_Ld_Coefs!$D$13*Step1_Features!M10+Step3_Ld_Coefs!$D$14*Step1_Features!N10+Step3_Ld_Coefs!$D$15*Step1_Features!O10+Step3_Ld_Coefs!$D$16*Step1_Features!P10+Step3_Ld_Coefs!$D$17*Step1_Features!Q10+Step3_Ld_Coefs!$D$18*Step1_Features!R10 -> 500.41551 | F9: =D9-E9 -> -1.3511621 | G9: =F9^2 -> 1.825639 | H9: =F9/D9*100 -> -0.27073906
A10: 8 | B10: =Raw_Data!B10 -> 0 | C10: =Raw_Data!C10 -> 10.280355 | D10: =Raw_Data!D10 -> 499.15296 | E10: =Step3_Ld_Coefs!$D$4*Step1_Features!D11+Step3_Ld_Coefs!$D$5*Step1_Features!E11+Step3_Ld_Coefs!$D$6*Step1_Features!F11+Step3_Ld_Coefs!$D$7*Step1_Features!G11+Step3_Ld_Coefs!$D$8*Step1_Features!H11+Step3_Ld_Coefs!$D$9*Step1_Features!I11+Step3_Ld_Coefs!$D$10*Step1_Features!J11+Step3_Ld_Coefs!$D$11*Step1_Features!K11+Step3_Ld_Coefs!$D$12*Step1_Features!L11+Step3_Ld_Coefs!$D$13*Step1_Features!M11+Step3_Ld_Coefs!$D$14*Step1_Features!N11+Step3_Ld_Coefs!$D$15*Step1_Features!O11+Step3_Ld_Coefs!$D$16*Step1_Features!P11+Step3_Ld_Coefs!$D$17*Step1_Features!Q11+Step3_Ld_Coefs!$D$18*Step1_Features!R11 -> 499.50564 | F10: =D10-E10 -> -0.35267914 | G10: =F10^2 -> 0.12438257 | H10: =F10/D10*100 -> -0.070655524
A11: 9 | B11: =Raw_Data!B11 -> -2.660752 | C11: =Raw_Data!C11 -> 9.930061 | D11: =Raw_Data!D11 -> 500.50879 | E11: =Step3_Ld_Coefs!$D$4*Step1_Features!D12+Step3_Ld_Coefs!$D$5*Step1_Features!E12+Step3_Ld_Coefs!$D$6*Step1_Features!F12+Step3_Ld_Coefs!$D$7*Step1_Features!G12+Step3_Ld_Coefs!$D$8*Step1_Features!H12+Step3_Ld_Coefs!$D$9*Step1_Features!I12+Step3_Ld_Coefs!$D$10*Step1_Features!J12+Step3_Ld_Coefs!$D$11*Step1_Features!K12+Step3_Ld_Coefs!$D$12*Step1_Features!L12+Step3_Ld_Coefs!$D$13*Step1_Features!M12+Step3_Ld_Coefs!$D$14*Step1_Features!N12+Step3_Ld_Coefs!$D$15*Step1_Features!O12+Step3_Ld_Coefs!$D$16*Step1_Features!P12+Step3_Ld_Coefs!$D$17*Step1_Features!Q12+Step3_Ld_Coefs!$D$18*Step1_Features!R12 -> 500.21337 | F11: =D11-E11 -> 0.29541936 | G11: =F11^2 -> 0.087272595 | H11: =F11/D11*100 -> 0.05902381
A12: 10 | B12: =Raw_Data!B12 -> -5.140178 | C12: =Raw_Data!C12 -> 8.903049 | D12: =Raw_Data!D12 -> 501.47484 | E12: =Step3_Ld_Coefs!$D$4*Step1_Features!D13+Step3_Ld_Coefs!$D$5*Step1_Features!E13+Step3_Ld_Coefs!$D$6*Step1_Features!F13+Step3_Ld_Coefs!$D$7*Step1_Features!G13+Step3_Ld_Coefs!$D$8*Step1_Features!H13+Step3_Ld_Coefs!$D$9*Step1_Features!I13+Step3_Ld_Coefs!$D$10*Step1_Features!J13+Step3_Ld_Coefs!$D$11*Step1_Features!K13+Step3_Ld_Coefs!$D$12*Step1_Features!L13+Step3_Ld_Coefs!$D$13*Step1_Features!M13+Step3_Ld_Coefs!$D$14*Step1_Features!N13+Step3_Ld_Coefs!$D$15*Step1_Features!O13+Step3_Ld_Coefs!$D$16*Step1_Features!P13+Step3_Ld_Coefs!$D$17*Step1_Features!Q13+Step3_Ld_Coefs!$D$18*Step1_Features!R13 -> 500.85872 | F12: =D12-E12 -> 0.61612539 | G12: =F12^2 -> 0.3796105 | H12: =F12/D12*100 -> 0.12286267
A13: 11 | B13: =Raw_Data!B13 -> -7.269309 | C13: =Raw_Data!C13 -> 7.269309 | D13: =Raw_Data!D13 -> 501.85677 | E13: =Step3_Ld_Coefs!$D$4*Step1_Features!D14+Step3_Ld_Coefs!$D$5*Step1_Features!E14+Step3_Ld_Coefs!$D$6*Step1_Features!F14+Step3_Ld_Coefs!$D$7*Step1_Features!G14+Step3_Ld_Coefs!$D$8*Step1_Features!H14+Step3_Ld_Coefs!$D$9*Step1_Features!I14+Step3_Ld_Coefs!$D$10*Step1_Features!J14+Step3_Ld_Coefs!$D$11*Step1_Features!K14+Step3_Ld_Coefs!$D$12*Step1_Features!L14+Step3_Ld_Coefs!$D$13*Step1_Features!M14+Step3_Ld_Coefs!$D$14*Step1_Features!N14+Step3_Ld_Coefs!$D$15*Step1_Features!O14+Step3_Ld_Coefs!$D$16*Step1_Features!P14+Step3_Ld_Coefs!$D$17*Step1_Features!Q14+Step3_Ld_Coefs!$D$18*Step1_Features!R14 -> 501.35917 | F13: =D13-E13 -> 0.49760551 | G13: =F13^2 -> 0.24761124 | H13: =F13/D13*100 -> 0.099152893
A14: 12 | B14: =Raw_Data!B14 -> -8.903049 | C14: =Raw_Data!C14 -> 5.140178 | D14: =Raw_Data!D14 -> 501.77728 | E14: =Step3_Ld_Coefs!$D$4*Step1_Features!D15+Step3_Ld_Coefs!$D$5*Step1_Features!E15+Step3_Ld_Coefs!$D$6*Step1_Features!F15+Step3_Ld_Coefs!$D$7*Step1_Features!G15+Step3_Ld_Coefs!$D$8*Step1_Features!H15+Step3_Ld_Coefs!$D$9*Step1_Features!I15+Step3_Ld_Coefs!$D$10*Step1_Features!J15+Step3_Ld_Coefs!$D$11*Step1_Features!K15+Step3_Ld_Coefs!$D$12*Step1_Features!L15+Step3_Ld_Coefs!$D$13*Step1_Features!M15+Step3_Ld_Coefs!$D$14*Step1_Features!N15+Step3_Ld_Coefs!$D$15*Step1_Features!O15+Step3_Ld_Coefs!$D$16*Step1_Features!P15+Step3_Ld_Coefs!$D$17*Step1_Features!Q15+Step3_Ld_Coefs!$D$18*Step1_Features!R15 -> 501.64812 | F14: =D14-E14 -> 0.12916606 | G14: =F14^2 -> 0.01668387 | H14: =F14/D14*100 -> 0.025741711
... A79: 77 | B79: =Raw_Data!B79 -> -102.80355 | C79: =Raw_Data!C79 -> 0 | D79: =Raw_Data!D79 -> 494.20608 | E79: =Step3_Ld_Coefs!$D$4*Step1_Features!D80+Step3_Ld_Coefs!$D$5*Step1_Features!E80+Step3_Ld_Coefs!$D$6*Step1_Features!F80+Step3_Ld_Coefs!$D$7*Step1_Features!G80+Step3_Ld_Coefs!$D$8*Step1_Features!H80+Step3_Ld_Coefs!$D$9*Step1_Features!I80+Step3_Ld_Coefs!$D$10*Step1_Features!J80+Step3_Ld_Coefs!$D$11*Step1_Features!K80+Step3_Ld_Coefs!$D$12*Step1_Features!L80+Step3_Ld_Coefs!$D$13*Step1_Features!M80+Step3_Ld_Coefs!$D$14*Step1_Features!N80+Step3_Ld_Coefs!$D$15*Step1_Features!O80+Step3_Ld_Coefs!$D$16*Step1_Features!P80+Step3_Ld_Coefs!$D$17*Step1_Features!Q80+Step3_Ld_Coefs!$D$18*Step1_Features!R80 -> 494.46439 | F79: =D79-E79 -> -0.25830969 | G79: =F79^2 -> 0.066723898 | H79: =F79/D79*100 -> -0.052267608
A80: Summary | D80: n = 77 | E80: =1-SUMPRODUCT((D3:D79-E3:E79)^2)/SUMPRODUCT((D3:D79-AVERAGE(D3:D79))^2) -> 0.99798819 | F80: =MAX(F3:F79,-MIN(F3:F79)) -> 1.6344279 | G80: =SQRT(SUMPRODUCT(G3:G79)/77) -> 0.62456119
A82: Error colour: green shading on all error cells (col F). Use conditional formatting in Excel to add red/amber thresholds.

Sheet Step5_Ld_Formula
A1: Step 5 — Final Excel Formula for Ld_uH = f(Id_ref, Iq_ref)
A2: Enter Id_ref in A6, Iq_ref in B6. Formula in C6 references coefficients from Step3.
A5: Id_ref (A) | B5: Iq_ref (A) | C5: Ld_uH (µH) | D5: Cross-check vs Step4 | E5: Note
A6: -30 | B6: 20 | C6: =Step3_Ld_Coefs!D4*1+Step3_Ld_Coefs!D5*A6+Step3_Ld_Coefs!D6*B6+Step3_Ld_Coefs!D7*A6^2+Step3_Ld_Coefs!D8*A6*B6+Step3_Ld_Coefs!D9*B6^2+Step3_Ld_Coefs!D10*A6^3+Step3_Ld_Coefs!D11*A6^2*B6+Step3_Ld_Coefs!D12*A6*B6^2+Step3_Ld_Coefs!D13*B6^3+Step3_Ld_Coefs!D14*A6^4+Step3_Ld_Coefs!D15*A6^3*B6+Step3_Ld_Coefs!D16*A6^2*B6^2+Step3_Ld_Coefs!D17*A6*B6^3+Step3_Ld_Coefs!D18*B6^4 -> 500.02828 | D6: =Step3_Ld_Coefs!$D$4*H6+Step3_Ld_Coefs!$D$5*I6+Step3_Ld_Coefs!$D$6*J6+Step3_Ld_Coefs!$D$7*K6+Step3_Ld_Coefs!$D$8*L6+Step3_Ld_Coefs!$D$9*M6+Step3_Ld_Coefs!$D$10*N6+Step3_Ld_Coefs!$D$11*O6+Step3_Ld_Coefs!$D$12*P6+Step3_Ld_Coefs!$D$13*Q6+Step3_Ld_Coefs!$D$14*R6+Step3_Ld_Coefs!$D$15*S6+Step3_Ld_Coefs!$D$16*T6+Step3_Ld_Coefs!$D$17*U6+Step3_Ld_Coefs!$D$18*V6 -> 500.02828 | E6: ← C6 and D6 must match. C6 uses explicit terms; D6 uses SUMPRODUCT. | G6: → helper features: | H6: =1 -> 1 | I6: =A6 -> -30 | J6: =B6 -> 20 | K6: =A6^2 -> 900 | L6: =A6*B6 -> -600 | M6: =B6^2 -> 400 | N6: =A6^3 -> -27000 | O6: =A6^2*B6 -> 18000 | P6: =A6*B6^2 -> -12000 | Q6: =B6^3 -> 8000 | R6: =A6^4 -> 810000 | S6: =A6^3*B6 -> -540000 | T6: =A6^2*B6^2 -> 360000 | U6: =A6*B6^3 -> -240000 | V6: =B6^4 -> 160000
A9: Term-by-term breakdown — coefficients pulled live from Step3_Ld_Coefs
A10: Feature | B10: β coefficient (from Step3 col D) | C10: Excel term in formula | D10: Value at Id=−30, Iq=20 | E10: β × feature value
A11: 1 (constant) | B11: =Step3_Ld_Coefs!D4 -> 500.41551 | C11: 'Step3_Ld_Coefs'!D4*1 | D11: =1 -> 1 | E11: =B11*D11 -> 500.41551
A12: Id | B12: =Step3_Ld_Coefs!D5 -> -0.17118854 | C12: 'Step3_Ld_Coefs'!D5*A6 | D12: =A6 -> -30 | E12: =B12*D12 -> 5.1356562
A13: Iq | B13: =Step3_Ld_Coefs!D6 -> 0.07899178 | C13: 'Step3_Ld_Coefs'!D6*B6 | D13: =B6 -> 20 | E13: =B13*D13 -> 1.5798356
A14: Id² | B14: =Step3_Ld_Coefs!D7 -> -0.0079838517 | C14: 'Step3_Ld_Coefs'!D7*A6^2 | D14: =A6^2 -> 900 | E14: =B14*D14 -> -7.1854665
A15: Id·Iq | B15: =Step3_Ld_Coefs!D8 -> -0.0078011761 | C15: 'Step3_Ld_Coefs'!D8*A6*B6 | D15: =A6*B6 -> -600 | E15: =B15*D15 -> 4.6807057
A16: Iq² | B16: =Step3_Ld_Coefs!D9 -> -0.018291945 | C16: 'Step3_Ld_Coefs'!D9*B6^2 | D16: =B6^2 -> 400 | E16: =B16*D16 -> -7.3167778
A17: Id³ | B17: =Step3_Ld_Coefs!D10 -> -9.3273657e-05 | C17: 'Step3_Ld_Coefs'!D10*A6^3 | D17: =A6^3 -> -27000 | E17: =B17*D17 -> 2.5183887
A18: Id²·Iq | B18: =Step3_Ld_Coefs!D11 -> -0.00014440794 | C18: 'Step3_Ld_Coefs'!D11*A6^2*B6 | D18: =A6^2*B6 -> 18000 | E18: =B18*D18 -> -2.599343
A19: Id·Iq² | B19: =Step3_Ld_Coefs!D12 -> -0.0001209361 | C19: 'Step3_Ld_Coefs'!D12*A6*B6^2 | D19: =A6*B6^2 -> -12000 | E19: =B19*D19 -> 1.4512332
A20: Iq³ | B20: =Step3_Ld_Coefs!D13 -> 0.00020428917 | C20: 'Step3_Ld_Coefs'!D13*B6^3 | D20: =B6^3 -> 8000 | E20: =B20*D20 -> 1.6343133
A21: Id⁴ | B21: =Step3_Ld_Coefs!D14 -> -3.6270832e-07 | C21: 'Step3_Ld_Coefs'!D14*A6^4 | D21: =A6^4 -> 810000 | E21: =B21*D21 -> -0.29379374
A22: Id³·Iq | B22: =Step3_Ld_Coefs!D15 -> -5.7514288e-07 | C22: 'Step3_Ld_Coefs'!D15*A6^3*B6 | D22: =A6^3*B6 -> -540000 | E22: =B22*D22 -> 0.31057715
A23: Id²·Iq² | B23: =Step3_Ld_Coefs!D16 -> 1.3937826e-07 | C23: 'Step3_Ld_Coefs'!D16*A6^2*B6^2 | D23: =A6^2*B6^2 -> 360000 | E23: =B23*D23 -> 0.050176174
A24: Id·Iq³ | B24: =Step3_Ld_Coefs!D17 -> 8.3138155e-07 | C24: 'Step3_Ld_Coefs'!D17*A6*B6^3 | D24: =A6*B6^3 -> -240000 | E24: =B24*D24 -> -0.19953157
A25: Iq⁴ | B25: =Step3_Ld_Coefs!D18 -> -9.5751922e-07 | C25: 'Step3_Ld_Coefs'!D18*B6^4 | D25: =B6^4 -> 160000 | E25: =B25*D25 -> -0.15320307
A26: Total | E26: =SUM(E11:E25) -> 500.02828

Sheet Step2_Lq_XtX
A1: Step 2 — XᵀX matrix (15×15) for Lq fit | Each cell = SUMPRODUCT of two feature columns from Step1
A2: Feature | B2: XᵀX — every cell =SUMPRODUCT(col_i of Step1, col_j of Step1)
A3: Feature | B3: 1 (constant) | C3: Id | D3: Iq | E3: Id² | F3: Id·Iq | G3: Iq² | H3: Id³ | I3: Id²·Iq | J3: Id·Iq² | K3: Iq³ | L3: Id⁴ | M3: Id³·Iq | N3: Id²·Iq² | O3: Id·Iq³ | P3: Iq⁴
A4: 1 (constant) | B4: =SUMPRODUCT(Step1_Features!D$4:D$80,Step1_Features!D$4:D$80) -> 77 | C4: =SUMPRODUCT(Step1_Features!D$4:D$80,Step1_Features!E$4:E$80) -> -2430.1037 | D4: =SUMPRODUCT(Step1_Features!D$4:D$80,Step1_Features!F$4:F$80) -> 2430.1037 | E4: =SUMPRODUCT(Step1_Features!D$4:D$80,Step1_Features!G$4:G$80) -> 142411.49 | F4: =SUMPRODUCT(Step1_Features!D$4:D$80,Step1_Features!H$4:H$80) -> -75926.702 | G4: =SUMPRODUCT(Step1_Features!D$4:D$80,Step1_Features!I$4:I$80) -> 142411.49 | H4: =SUMPRODUCT(Step1_Features!D$4:D$80,Step1_Features!J$4:J$80) -> -10013125 | I4: =SUMPRODUCT(Step1_Features!D$4:D$80,Step1_Features!K$4:K$80) -> 4112372.5 | J4: =SUMPRODUCT(Step1_Features!D$4:D$80,Step1_Features!L$4:L$80) -> -4112372.5 | K4: =SUMPRODUCT(Step1_Features!D$4:D$80,Step1_Features!M$4:M$80) -> 10013125 | L4: =SUMPRODUCT(Step1_Features!D$4:D$80,Step1_Features!N$4:N$80) -> 7.781294e+08 | M4: =SUMPRODUCT(Step1_Features!D$4:D$80,Step1_Features!O$4:O$80) -> -2.6400168e+08 | N4: =SUMPRODUCT(Step1_Features!D$4:D$80,Step1_Features!P$4:P$80) -> 2.1221711e+08 | O4: =SUMPRODUCT(Step1_Features!D$4:D$80,Step1_Features!Q$4:Q$80) -> -2.6400168e+08 | P4: =SUMPRODUCT(Step1_Features!D$4:D$80,Step1_Features!R$4:R$80) -> 7.781294e+08
A5: Id | B5: =SUMPRODUCT(Step1_Features!E$4:E$80,Step1_Features!D$4:D$80) -> -2430.1037 | C5: =SUMPRODUCT(Step1_Features!E$4:E$80,Step1_Features!E$4:E$80) -> 142411.49 | D5: =SUMPRODUCT(Step1_Features!E$4:E$80,Step1_Features!F$4:F$80) -> -75926.702 | E5: =SUMPRODUCT(Step1_Features!E$4:E$80,Step1_Features!G$4:G$80) -> -10013125 | F5: =SUMPRODUCT(Step1_Features!E$4:E$80,Step1_Features!H$4:H$80) -> 4112372.5 | G5: =SUMPRODUCT(Step1_Features!E$4:E$80,Step1_Features!I$4:I$80) -> -4112372.5 | H5: =SUMPRODUCT(Step1_Features!E$4:E$80,Step1_Features!J$4:J$80) -> 7.781294e+08 | I5: =SUMPRODUCT(Step1_Features!E$4:E$80,Step1_Features!K$4:K$80) -> -2.6400168e+08 | J5: =SUMPRODUCT(Step1_Features!E$4:E$80,Step1_Features!L$4:L$80) -> 2.1221711e+08 | K5: =SUMPRODUCT(Step1_Features!E$4:E$80,Step1_Features!M$4:M$80) -> -2.6400168e+08 | L5: =SUMPRODUCT(Step1_Features!E$4:E$80,Step1_Features!N$4:N$80) -> -6.4333891e+10 | M5: =SUMPRODUCT(Step1_Features!E$4:E$80,Step1_Features!O$4:O$80) -> 1.8809254e+10 | N5: =SUMPRODUCT(Step1_Features!E$4:E$80,Step1_Features!P$4:P$80) -> -1.2917933e+10 | O5: =SUMPRODUCT(Step1_Features!E$4:E$80,Step1_Features!Q$4:Q$80) -> 1.2917933e+10 | P5: =SUMPRODUCT(Step1_Features!E$4:E$80,Step1_Features!R$4:R$80) -> -1.8809254e+10
A6: Iq | B6: =SUMPRODUCT(Step1_Features!F$4:F$80,Step1_Features!D$4:D$80) -> 2430.1037 | C6: =SUMPRODUCT(Step1_Features!F$4:F$80,Step1_Features!E$4:E$80) -> -75926.702 | D6: =SUMPRODUCT(Step1_Features!F$4:F$80,Step1_Features!F$4:F$80) -> 142411.49 | E6: =SUMPRODUCT(Step1_Features!F$4:F$80,Step1_Features!G$4:G$80) -> 4112372.5 | F6: =SUMPRODUCT(Step1_Features!F$4:F$80,Step1_Features!H$4:H$80) -> -4112372.5 | G6: =SUMPRODUCT(Step1_Features!F$4:F$80,Step1_Features!I$4:I$80) -> 10013125 | H6: =SUMPRODUCT(Step1_Features!F$4:F$80,Step1_Features!J$4:J$80) -> -2.6400168e+08 | I6: =SUMPRODUCT(Step1_Features!F$4:F$80,Step1_Features!K$4:K$80) -> 2.1221711e+08 | J6: =SUMPRODUCT(Step1_Features!F$4:F$80,Step1_Features!L$4:L$80) -> -2.6400168e+08 | K6: =SUMPRODUCT(Step1_Features!F$4:F$80,Step1_Features!M$4:M$80) -> 7.781294e+08 | L6: =SUMPRODUCT(Step1_Features!F$4:F$80,Step1_Features!N$4:N$80) -> 1.8809254e+10 | M6: =SUMPRODUCT(Step1_Features!F$4:F$80,Step1_Features!O$4:O$80) -> -1.2917933e+10 | N6: =SUMPRODUCT(Step1_Features!F$4:F$80,Step1_Features!P$4:P$80) -> 1.2917933e+10 | O6: =SUMPRODUCT(Step1_Features!F$4:F$80,Step1_Features!Q$4:Q$80) -> -1.8809254e+10 | P6: =SUMPRODUCT(Step1_Features!F$4:F$80,Step1_Features!R$4:R$80) -> 6.4333891e+10
A7: Id² | B7: =SUMPRODUCT(Step1_Features!G$4:G$80,Step1_Features!D$4:D$80) -> 142411.49 | C7: =SUMPRODUCT(Step1_Features!G$4:G$80,Step1_Features!E$4:E$80) -> -10013125 | D7: =SUMPRODUCT(Step1_Features!G$4:G$80,Step1_Features!F$4:F$80) -> 4112372.5 | E7: =SUMPRODUCT(Step1_Features!G$4:G$80,Step1_Features!G$4:G$80) -> 7.781294e+08 | F7: =SUMPRODUCT(Step1_Features!G$4:G$80,Step1_Features!H$4:H$80) -> -2.6400168e+08 | G7: =SUMPRODUCT(Step1_Features!G$4:G$80,Step1_Features!I$4:I$80) -> 2.1221711e+08 | H7: =SUMPRODUCT(Step1_Features!G$4:G$80,Step1_Features!J$4:J$80) -> -6.4333891e+10 | I7: =SUMPRODUCT(Step1_Features!G$4:G$80,Step1_Features!K$4:K$80) -> 1.8809254e+10 | J7: =SUMPRODUCT(Step1_Features!G$4:G$80,Step1_Features!L$4:L$80) -> -1.2917933e+10 | K7: =SUMPRODUCT(Step1_Features!G$4:G$80,Step1_Features!M$4:M$80) -> 1.2917933e+10 | L7: =SUMPRODUCT(Step1_Features!G$4:G$80,Step1_Features!N$4:N$80) -> 5.5466092e+12 | M7: =SUMPRODUCT(Step1_Features!G$4:G$80,Step1_Features!O$4:O$80) -> -1.4348388e+12 | N7: =SUMPRODUCT(Step1_Features!G$4:G$80,Step1_Features!P$4:P$80) -> 8.7578042e+11 | O7: =SUMPRODUCT(Step1_Features!G$4:G$80,Step1_Features!Q$4:Q$80) -> -7.4413256e+11 | P7: =SUMPRODUCT(Step1_Features!G$4:G$80,Step1_Features!R$4:R$80) -> 8.7578042e+11
A8: Id·Iq | B8: =SUMPRODUCT(Step1_Features!H$4:H$80,Step1_Features!D$4:D$80) -> -75926.702 | C8: =SUMPRODUCT(Step1_Features!H$4:H$80,Step1_Features!E$4:E$80) -> 4112372.5 | D8: =SUMPRODUCT(Step1_Features!H$4:H$80,Step1_Features!F$4:F$80) -> -4112372.5 | E8: =SUMPRODUCT(Step1_Features!H$4:H$80,Step1_Features!G$4:G$80) -> -2.6400168e+08 | F8: =SUMPRODUCT(Step1_Features!H$4:H$80,Step1_Features!H$4:H$80) -> 2.1221711e+08 | G8: =SUMPRODUCT(Step1_Features!H$4:H$80,Step1_Features!I$4:I$80) -> -2.6400168e+08 | H8: =SUMPRODUCT(Step1_Features!H$4:H$80,Step1_Features!J$4:J$80) -> 1.8809254e+10 | I8: =SUMPRODUCT(Step1_Features!H$4:H$80,Step1_Features!K$4:K$80) -> -1.2917933e+10 | J8: =SUMPRODUCT(Step1_Features!H$4:H$80,Step1_Features!L$4:L$80) -> 1.2917933e+10 | K8: =SUMPRODUCT(Step1_Features!H$4:H$80,Step1_Features!M$4:M$80) -> -1.8809254e+10 | L8: =SUMPRODUCT(Step1_Features!H$4:H$80,Step1_Features!N$4:N$80) -> -1.4348388e+12 | M8: =SUMPRODUCT(Step1_Features!H$4:H$80,Step1_Features!O$4:O$80) -> 8.7578042e+11 | N8: =SUMPRODUCT(Step1_Features!H$4:H$80,Step1_Features!P$4:P$80) -> -7.4413256e+11 | O8: =SUMPRODUCT(Step1_Features!H$4:H$80,Step1_Features!Q$4:Q$80) -> 8.7578042e+11 | P8: =SUMPRODUCT(Step1_Features!H$4:H$80,Step1_Features!R$4:R$80) -> -1.4348388e+12
A9: Iq² | B9: =SUMPRODUCT(Step1_Features!I$4:I$80,Step1_Features!D$4:D$80) -> 142411.49 | C9: =SUMPRODUCT(Step1_Features!I$4:I$80,Step1_Features!E$4:E$80) -> -4112372.5 | D9: =SUMPRODUCT(Step1_Features!I$4:I$80,Step1_Features!F$4:F$80) -> 10013125 | E9: =SUMPRODUCT(Step1_Features!I$4:I$80,Step1_Features!G$4:G$80) -> 2.1221711e+08 | F9: =SUMPRODUCT(Step1_Features!I$4:I$80,Step1_Features!H$4:H$80) -> -2.6400168e+08 | G9: =SUMPRODUCT(Step1_Features!I$4:I$80,Step1_Features!I$4:I$80) -> 7.781294e+08 | H9: =SUMPRODUCT(Step1_Features!I$4:I$80,Step1_Features!J$4:J$80) -> -1.2917933e+10 | I9: =SUMPRODUCT(Step1_Features!I$4:I$80,Step1_Features!K$4:K$80) -> 1.2917933e+10 | J9: =SUMPRODUCT(Step1_Features!I$4:I$80,Step1_Features!L$4:L$80) -> -1.8809254e+10 | K9: =SUMPRODUCT(Step1_Features!I$4:I$80,Step1_Features!M$4:M$80) -> 6.4333891e+10 | L9: =SUMPRODUCT(Step1_Features!I$4:I$80,Step1_Features!N$4:N$80) -> 8.7578042e+11 | M9: =SUMPRODUCT(Step1_Features!I$4:I$80,Step1_Features!O$4:O$80) -> -7.4413256e+11 | N9: =SUMPRODUCT(Step1_Features!I$4:I$80,Step1_Features!P$4:P$80) -> 8.7578042e+11 | O9: =SUMPRODUCT(Step1_Features!I$4:I$80,Step1_Features!Q$4:Q$80) -> -1.4348388e+12 | P9: =SUMPRODUCT(Step1_Features!I$4:I$80,Step1_Features!R$4:R$80) -> 5.5466092e+12
A10: Id³ | B10: =SUMPRODUCT(Step1_Features!J$4:J$80,Step1_Features!D$4:D$80) -> -10013125 | C10: =SUMPRODUCT(Step1_Features!J$4:J$80,Step1_Features!E$4:E$80) -> 7.781294e+08 | D10: =SUMPRODUCT(Step1_Features!J$4:J$80,Step1_Features!F$4:F$80) -> -2.6400168e+08 | E10: =SUMPRODUCT(Step1_Features!J$4:J$80,Step1_Features!G$4:G$80) -> -6.4333891e+10 | F10: =SUMPRODUCT(Step1_Features!J$4:J$80,Step1_Features!H$4:H$80) -> 1.8809254e+10 | G10: =SUMPRODUCT(Step1_Features!J$4:J$80,Step1_Features!I$4:I$80) -> -1.2917933e+10 | H10: =SUMPRODUCT(Step1_Features!J$4:J$80,Step1_Features!J$4:J$80) -> 5.5466092e+12 | I10: =SUMPRODUCT(Step1_Features!J$4:J$80,Step1_Features!K$4:K$80) -> -1.4348388e+12 | J10: =SUMPRODUCT(Step1_Features!J$4:J$80,Step1_Features!L$4:L$80) -> 8.7578042e+11 | K10: =SUMPRODUCT(Step1_Features!J$4:J$80,Step1_Features!M$4:M$80) -> -7.4413256e+11 | L10: =SUMPRODUCT(Step1_Features!J$4:J$80,Step1_Features!N$4:N$80) -> -4.9283974e+14 | M10: =SUMPRODUCT(Step1_Features!J$4:J$80,Step1_Features!O$4:O$80) -> 1.1483294e+14 | N10: =SUMPRODUCT(Step1_Features!J$4:J$80,Step1_Features!P$4:P$80) -> -63854166014521 | O10: =SUMPRODUCT(Step1_Features!J$4:J$80,Step1_Features!Q$4:Q$80) -> 4.7927264e+13 | P10: =SUMPRODUCT(Step1_Features!J$4:J$80,Step1_Features!R$4:R$80) -> -4.7927264e+13
A11: Id²·Iq | B11: =SUMPRODUCT(Step1_Features!K$4:K$80,Step1_Features!D$4:D$80) -> 4112372.5 | C11: =SUMPRODUCT(Step1_Features!K$4:K$80,Step1_Features!E$4:E$80) -> -2.6400168e+08 | D11: =SUMPRODUCT(Step1_Features!K$4:K$80,Step1_Features!F$4:F$80) -> 2.1221711e+08 | E11: =SUMPRODUCT(Step1_Features!K$4:K$80,Step1_Features!G$4:G$80) -> 1.8809254e+10 | F11: =SUMPRODUCT(Step1_Features!K$4:K$80,Step1_Features!H$4:H$80) -> -1.2917933e+10 | G11: =SUMPRODUCT(Step1_Features!K$4:K$80,Step1_Features!I$4:I$80) -> 1.2917933e+10 | H11: =SUMPRODUCT(Step1_Features!K$4:K$80,Step1_Features!J$4:J$80) -> -1.4348388e+12 | I11: =SUMPRODUCT(Step1_Features!K$4:K$80,Step1_Features!K$4:K$80) -> 8.7578042e+11 | J11: =SUMPRODUCT(Step1_Features!K$4:K$80,Step1_Features!L$4:L$80) -> -7.4413256e+11 | K11: =SUMPRODUCT(Step1_Features!K$4:K$80,Step1_Features!M$4:M$80) -> 8.7578042e+11 | L11: =SUMPRODUCT(Step1_Features!K$4:K$80,Step1_Features!N$4:N$80) -> 1.1483294e+14 | M11: =SUMPRODUCT(Step1_Features!K$4:K$80,Step1_Features!O$4:O$80) -> -63854166014521 | N11: =SUMPRODUCT(Step1_Features!K$4:K$80,Step1_Features!P$4:P$80) -> 4.7927264e+13 | O11: =SUMPRODUCT(Step1_Features!K$4:K$80,Step1_Features!Q$4:Q$80) -> -4.7927264e+13 | P11: =SUMPRODUCT(Step1_Features!K$4:K$80,Step1_Features!R$4:R$80) -> 6.3854166e+13
A12: Id·Iq² | B12: =SUMPRODUCT(Step1_Features!L$4:L$80,Step1_Features!D$4:D$80) -> -4112372.5 | C12: =SUMPRODUCT(Step1_Features!L$4:L$80,Step1_Features!E$4:E$80) -> 2.1221711e+08 | D12: =SUMPRODUCT(Step1_Features!L$4:L$80,Step1_Features!F$4:F$80) -> -2.6400168e+08 | E12: =SUMPRODUCT(Step1_Features!L$4:L$80,Step1_Features!G$4:G$80) -> -1.2917933e+10 | F12: =SUMPRODUCT(Step1_Features!L$4:L$80,Step1_Features!H$4:H$80) -> 1.2917933e+10 | G12: =SUMPRODUCT(Step1_Features!L$4:L$80,Step1_Features!I$4:I$80) -> -1.8809254e+10 | H12: =SUMPRODUCT(Step1_Features!L$4:L$80,Step1_Features!J$4:J$80) -> 8.7578042e+11 | I12: =SUMPRODUCT(Step1_Features!L$4:L$80,Step1_Features!K$4:K$80) -> -7.4413256e+11 | J12: =SUMPRODUCT(Step1_Features!L$4:L$80,Step1_Features!L$4:L$80) -> 8.7578042e+11 | K12: =SUMPRODUCT(Step1_Features!L$4:L$80,Step1_Features!M$4:M$80) -> -1.4348388e+12 | L12: =SUMPRODUCT(Step1_Features!L$4:L$80,Step1_Features!N$4:N$80) -> -6.3854166e+13 | M12: =SUMPRODUCT(Step1_Features!L$4:L$80,Step1_Features!O$4:O$80) -> 4.7927264e+13 | N12: =SUMPRODUCT(Step1_Features!L$4:L$80,Step1_Features!P$4:P$80) -> -4.7927264e+13 | O12: =SUMPRODUCT(Step1_Features!L$4:L$80,Step1_Features!Q$4:Q$80) -> 6.3854166e+13 | P12: =SUMPRODUCT(Step1_Features!L$4:L$80,Step1_Features!R$4:R$80) -> -1.1483294e+14
